<?xml version="1.0" encoding="utf-8"?>
<!-- This URDF was automatically created by SolidWorks to URDF Exporter! Originally created by Stephen Brawner (brawner@gmail.com) 
     Commit Version: 1.6.0-4-g7f85cfe  Build Version: 1.6.7995.38578
     For more information, please see http://wiki.ros.org/sw_urdf_exporter -->
<robot
  name="neobot">
  <link
    name="base_link">
    <inertial>
      <origin
        xyz="-0.049722 -9.9913E-06 -0.084819"
        rpy="0 0 0" />
      <mass
        value="1.5717" />
      <inertia
        ixx="0.0060442"
        ixy="-3.7043E-08"
        ixz="-1.2571E-07"
        iyy="0.0036668"
        iyz="2.5938E-06"
        izz="0.0075429" />
    </inertial>
    <visual>
      <origin
        xyz="0 0 0"
        rpy="0 0 0" />
      <geometry>
        <mesh
          filename="../meshes/base_link.STL" />
      </geometry>
      <material
        name="">
        <color
          rgba="0.69804 0.69804 0.69804 1" />
      </material>
    </visual>
    <collision>
      <origin
        xyz="-0.01 0 -0.1"
        rpy="0 0 0" />
      <geometry>
        <!-- <mesh
          filename="../meshes/base_link.STL" /> -->
          <box
            size="0.25 0.4 0.2" />
      </geometry>
    </collision>
  </link>
  <link
    name="l_hip_roll_link">
    <inertial>
      <origin
        xyz="0.103909738464143 -3.97098926263606E-06 0.0636310651266468"
        rpy="0 0 0" />
      <mass
        value="0.648421423606201" />
      <inertia
        ixx="0.000282994722250328"
        ixy="-1.57245814873796E-08"
        ixz="-4.20862997652685E-06"
        iyy="0.000498015404717495"
        iyz="3.00328977499768E-08"
        izz="0.000603045479504104" />
    </inertial>
    <visual>
      <origin
        xyz="0 0 0"
        rpy="0 0 0" />
      <geometry>
        <mesh
          filename="../meshes/l_hip_roll_link.STL" />
      </geometry>
      <material
        name="">
        <color
          rgba="0.698039215686274 0.698039215686274 0.698039215686274 1" />
      </material>
    </visual>
    <!-- <collision>
      <origin
        xyz="0 0 0"
        rpy="0 0 0" />
      <geometry>
        <mesh
          filename="../meshes/l_hip_roll_link.STL" />
      </geometry>
    </collision> -->
  </link>
  <joint
    name="l_hip_roll_joint"
    type="revolute">
    <origin
      xyz="-0.1051 0.13547 -0.13166"
      rpy="0 0 0" />
    <parent
      link="base_link" />
    <child
      link="l_hip_roll_link" />
    <axis
      xyz="-1 0 0" />
    <limit
      lower="-0.17"
      upper="0.17"
      effort="12"
      velocity="20" />
  </joint>
  <link
    name="l_hip_yaw_Link">
    <inertial>
      <origin
        xyz="-0.00021759 -3.5457E-05 -0.077147"
        rpy="0 0 0" />
      <mass
        value="0.85237" />
      <inertia
        ixx="0.00044314"
        ixy="-5.9797E-08"
        ixz="-1.1239E-06"
        iyy="0.00071592"
        iyz="-1.3444E-07"
        izz="0.00042552" />
    </inertial>
    <visual>
      <origin
        xyz="0 0 0"
        rpy="0 0 0" />
      <geometry>
        <mesh
          filename="../meshes/l_hip_yaw_Link.STL" />
      </geometry>
      <material
        name="">
        <color
          rgba="0.69804 0.69804 0.69804 1" />
      </material>
    </visual>
    <!-- <collision>
      <origin
        xyz="0 0 0"
        rpy="0 0 0" />
      <geometry>
        <mesh
          filename="../meshes/l_hip_yaw_Link.STL" />
      </geometry>
    </collision> -->
  </link>
  <joint
    name="l_hip_yaw_joint"
    type="revolute">
    <origin
      xyz="0.096507 0 0.067801"
      rpy="0 0 0" />
    <parent
      link="l_hip_roll_link" />
    <child
      link="l_hip_yaw_Link" />
    <axis
      xyz="0 0 1" />
    <limit
      lower="-0.17"
      upper="0.17"
      effort="12"
      velocity="20" />
  </joint>
  <link
    name="l_hip_pitch_link">
    <inertial>
      <origin
        xyz="0.00955178651124174 0.034752834986304 -0.1183383304379"
        rpy="0 0 0" />
      <mass
        value="0.328147864580731" />
      <inertia
        ixx="0.00176129627592422"
        ixy="2.76261752694052E-08"
        ixz="-0.000204351589291086"
        iyy="0.00188028872905888"
        iyz="-3.00639533797618E-08"
        izz="0.00021756723505753" />
    </inertial>
    <visual>
      <origin
        xyz="0 0 0"
        rpy="0 0 0" />
      <geometry>
        <mesh
          filename="../meshes/l_hip_pitch_link.STL" />
      </geometry>
      <material
        name="">
        <color
          rgba="0.698039215686274 0.698039215686274 0.698039215686274 1" />
      </material>
    </visual>
    <!-- <collision>
      <origin
        xyz="0 0 0"
        rpy="0 0 0" />
      <geometry>
        <mesh
          filename="../meshes/l_hip_pitch_link.STL" />
      </geometry>
    </collision> -->
  </link>
  <joint
    name="l_hip_pitch_joint"
    type="revolute">
    <origin
      xyz="-0.0001353 -0.035534 -0.08901"
      rpy="0 0 0" />
    <parent
      link="l_hip_yaw_Link" />
    <child
      link="l_hip_pitch_link" />
    <axis
      xyz="0 -1 0" />
    <limit
      lower="-1"
      upper="1"
      effort="12"
      velocity="20" />
  </joint>
  <link
    name="l_knee_pitch_link">
    <inertial>
      <origin
        xyz="-0.0136974895857442 0.0202409686967844 -0.103891841170742"
        rpy="0 0 0" />
      <mass
        value="0.553642994090125" />
      <inertia
        ixx="0.00222573138180942"
        ixy="-5.40239327040706E-06"
        ixz="0.000121404246279922"
        iyy="0.00235586663629424"
        iyz="-1.82284968948355E-06"
        izz="0.000204982816740747" />
    </inertial>
    <visual>
      <origin
        xyz="0 0 0"
        rpy="0 0 0" />
      <geometry>
        <mesh
          filename="../meshes/l_knee_pitch_link.STL" />
      </geometry>
      <material
        name="">
        <color
          rgba="0.698039215686274 0.698039215686274 0.698039215686274 1" />
      </material>
    </visual>
    <!-- <collision>
      <origin
        xyz="0 0 0"
        rpy="0 0 0" />
      <geometry>
        <mesh
          filename="../meshes/l_knee_pitch_link.STL" />
      </geometry>
    </collision> -->
  </link>
  <joint
    name="l_knee_pitch_joint"
    type="revolute">
    <origin
      xyz="0.034381 0.0355 -0.26839"
      rpy="0 0 0" />
    <parent
      link="l_hip_pitch_link" />
    <child
      link="l_knee_pitch_link" />
    <axis
      xyz="0 -1 0" />
    <limit
      lower="-0.7"
      upper="0.7"
      effort="12"
      velocity="20" />
  </joint>
  <link
    name="l_ankle_pitch_link">
    <inertial>
      <origin
        xyz="-0.00189683913633476 1.67769909312221E-07 -0.0298482040852532"
        rpy="0 0 0" />
      <mass
        value="0.0728791047521293" />
      <inertia
        ixx="3.19487900265831E-05"
        ixy="8.42941135557786E-09"
        ixz="-6.92959842897416E-06"
        iyy="0.000143229996313793"
        iyz="-2.818180745231E-10"
        izz="0.000151212385881323" />
    </inertial>
    <visual>
      <origin
        xyz="0 0 0"
        rpy="0 0 0" />
      <geometry>
        <mesh
          filename="../meshes/l_ankle_pitch_link.STL" />
      </geometry>
      <material
        name="">
        <color
          rgba="0.698039215686274 0.698039215686274 0.698039215686274 1" />
      </material>
    </visual>
    <collision>
      <origin
        xyz="0 0 0"
        rpy="0 0 0" />
      <geometry>
        <mesh
          filename="../meshes/l_ankle_pitch_link.STL" />
      </geometry>
    </collision>
  </link>
  <joint
    name="l_ankle_pitch_joint"
    type="revolute">
    <origin
      xyz="-0.017289 0 -0.2881"
      rpy="0 0 0" />
    <parent
      link="l_knee_pitch_link" />
    <child
      link="l_ankle_pitch_link" />
    <axis
      xyz="0 -1 0" />
    <limit
      lower="-0.35"
      upper="0.35"
      effort="12"
      velocity="20" />
  </joint>
  <link
    name="r_hip_roll_link">
    <inertial>
      <origin
        xyz="0.103947627647573 0.000108199441406748 0.0636310652535997"
        rpy="0 0 0" />
      <mass
        value="0.648421426114879" />
      <inertia
        ixx="0.000284679594506008"
        ixy="-1.99379177307477E-06"
        ixz="-4.19024436614062E-06"
        iyy="0.000496330529310536"
        iyz="2.10273470122241E-08"
        izz="0.000603045475994004" />
    </inertial>
    <visual>
      <origin
        xyz="0 0 0"
        rpy="0 0 0" />
      <geometry>
        <mesh
          filename="../meshes/r_hip_roll_link.STL" />
      </geometry>
      <material
        name="">
        <color
          rgba="0.698039215686274 0.698039215686274 0.698039215686274 1" />
      </material>
    </visual>
    <!-- <collision>
      <origin
        xyz="0 0 0"
        rpy="0 0 0" />
      <geometry>
        <mesh
          filename="../meshes/r_hip_roll_link.STL" />
      </geometry>
    </collision> -->
  </link>
  <joint
    name="r_hip_roll_joint"
    type="revolute">
    <origin
      xyz="-0.1051 -0.13511 -0.13166"
      rpy="0 0 0" />
    <parent
      link="base_link" />
    <child
      link="r_hip_roll_link" />
    <axis
      xyz="-1 0 0" />
    <limit
      lower="-0.17"
      upper="0.17"
      effort="12"
      velocity="20" />
  </joint>
  <link
    name="r_hip_yaw_Link">
    <inertial>
      <origin
        xyz="-0.000457408192366527 3.54653860826781E-05 -0.0842825237648493"
        rpy="0 0 0" />
      <mass
        value="0.852368482391641" />
      <inertia
        ixx="0.000441396724428936"
        ixy="4.4145823371947E-08"
        ixz="-2.61445722661877E-06"
        iyy="0.000715917636171953"
        iyz="1.49506771018755E-07"
        izz="0.000427270473729929" />
    </inertial>
    <visual>
      <origin
        xyz="0 0 0"
        rpy="0 0 0" />
      <geometry>
        <mesh
          filename="../meshes/r_hip_yaw_Link.STL" />
      </geometry>
      <material
        name="">
        <color
          rgba="0.698039215686274 0.698039215686274 0.698039215686274 1" />
      </material>
    </visual>
    <!-- <collision>
      <origin
        xyz="0 0 0"
        rpy="0 0 0" />
      <geometry>
        <mesh
          filename="../meshes/r_hip_yaw_Link.STL" />
      </geometry>
    </collision> -->
  </link>
  <joint
    name="r_hip_yaw_joint"
    type="revolute">
    <origin
      xyz="0.096507 0 0.074566"
      rpy="0 0 0" />
    <parent
      link="r_hip_roll_link" />
    <child
      link="r_hip_yaw_Link" />
    <axis
      xyz="0 0 1" />
    <limit
      lower="-0.17"
      upper="0.17"
      effort="12"
      velocity="20" />
  </joint>
  <link
    name="r_hip_pitch_link">
    <inertial>
      <origin
        xyz="0.00955180391882013 -0.034567776822228 -0.118338323541744"
        rpy="0 0 0" />
      <mass
        value="0.32814787394588" />
      <inertia
        ixx="0.00176129624550574"
        ixy="-2.76266034801465E-08"
        ixz="-0.000204351609171592"
        iyy="0.00188028870209282"
        iyz="3.00633952258311E-08"
        izz="0.000217567236558297" />
    </inertial>
    <visual>
      <origin
        xyz="0 0 0"
        rpy="0 0 0" />
      <geometry>
        <mesh
          filename="../meshes/r_hip_pitch_link.STL" />
      </geometry>
      <material
        name="">
        <color
          rgba="0.698039215686274 0.698039215686274 0.698039215686274 1" />
      </material>
    </visual>
    <!-- <collision>
      <origin
        xyz="0 0 0"
        rpy="0 0 0" />
      <geometry>
        <mesh
          filename="../meshes/r_hip_pitch_link.STL" />
      </geometry>
    </collision> -->
  </link>
  <joint
    name="r_hip_pitch_joint"
    type="revolute">
    <origin
      xyz="-0.00013529 0.035334 -0.095774"
      rpy="0 0 0" />
    <parent
      link="r_hip_yaw_Link" />
    <child
      link="r_hip_pitch_link" />
    <axis
      xyz="0 -1 0" />
    <limit
      lower="-1"
      upper="1"
      effort="12"
      velocity="20" />
  </joint>
  <link
    name="r_knee_pitch_link">
    <inertial>
      <origin
        xyz="-0.0139417307129494 -0.00418659301631841 -0.10375206661893"
        rpy="0 0 0" />
      <mass
        value="0.553642879390274" />
      <inertia
        ixx="0.00222920568706164"
        ixy="5.3606594748062E-06"
        ixz="0.00011936397865762"
        iyy="0.00235587011505753"
        iyz="1.84660619447914E-06"
        izz="0.000201511998923169" />
    </inertial>
    <visual>
      <origin
        xyz="0 0 0"
        rpy="0 0 0" />
      <geometry>
        <mesh
          filename="../meshes/r_knee_pitch_link.STL" />
      </geometry>
      <material
        name="">
        <color
          rgba="0.698039215686274 0.698039215686274 0.698039215686274 1" />
      </material>
    </visual>
    <!-- <collision>
      <origin
        xyz="0 0 0"
        rpy="0 0 0" />
      <geometry>
        <mesh
          filename="../meshes/r_knee_pitch_link.STL" />
      </geometry>
    </collision> -->
  </link>
  <joint
    name="r_knee_pitch_joint"
    type="revolute">
    <origin
      xyz="0.034381 -0.05137 -0.26839"
      rpy="0 0 0" />
    <parent
      link="r_hip_pitch_link" />
    <child
      link="r_knee_pitch_link" />
    <axis
      xyz="0 1 0" />
    <limit
      lower="-1"
      upper="1"
      effort="12"
      velocity="20" />
  </joint>
  <link
    name="r_ankle_pitch_link">
    <inertial>
      <origin
        xyz="-0.00189730777409582 -2.247001487099E-07 -0.0298481957351253"
        rpy="0 0 0" />
      <mass
        value="0.0728783502589278" />
      <inertia
        ixx="3.19489307609195E-05"
        ixy="-8.72503866142916E-09"
        ixz="-6.92956681283729E-06"
        iyy="0.000143228520888445"
        iyz="3.58580278806448E-10"
        izz="0.000151211185402427" />
    </inertial>
    <visual>
      <origin
        xyz="0 0 0"
        rpy="0 0 0" />
      <geometry>
        <mesh
          filename="../meshes/r_ankle_pitch_link.STL" />
      </geometry>
      <material
        name="">
        <color
          rgba="0.698039215686274 0.698039215686274 0.698039215686274 1" />
      </material>
    </visual>
    <collision>
      <origin
        xyz="0 0 0"
        rpy="0 0 0" />
      <geometry>
        <mesh
          filename="../meshes/r_ankle_pitch_link.STL" />
      </geometry>
    </collision>
  </link>
  <joint
    name="r_ankle_pitch_joint"
    type="revolute">
    <origin
      xyz="-0.017289 0.016054 -0.2881"
      rpy="0 0 0" />
    <parent
      link="r_knee_pitch_link" />
    <child
      link="r_ankle_pitch_link" />
    <axis
      xyz="0 1 0" />
    <limit
      lower="-0.35"
      upper="0.35"
      effort="12"
      velocity="20" />
  </joint>
</robot>