<mujoco model="cw2(edit inertia)">
    <compiler angle="radian" meshdir="../meshes/" />
    <default>
        <joint limited="true" damping="0.001" armature="0.01" frictionloss="0.1"/>
        <motor ctrllimited="true"/>
        <geom condim="4" contype="1" conaffinity="15" solref="0.001 2" friction="0.9 0.2 0.2"/>
        <equality solref="0.001 2"/>
    </default>
    <size njmax="500" nconmax="100" />
    <asset>
        <mesh name="base_link" file="base_link.STL" />
        <mesh name="r_hip_pitch_link" file="r_hip_pitch_link.STL" />
        <mesh name="r_hip_roll_link" file="r_hip_roll_link.STL" />
        <mesh name="r_knee_pitch_link" file="r_knee_pitch_link.STL" />
        <mesh name="l_hip_pitch_link" file="l_hip_pitch_link.STL" />
        <mesh name="l_hip_roll_link" file="l_hip_roll_link.STL" />
        <mesh name="l_knee_pitch_link" file="l_knee_pitch_link.STL" />
    </asset>
    <worldbody>
        <body name="base_link" pos="0 0 0.7">
            <inertial pos="-0.010262 5.2244e-05 -0.0059008" quat="0.999866 0.000239769 0.016394 -0.000309359" mass="2.40698" diaginertia="0.0145597 0.0127086 0.0046103" />
            <joint name="floating_base_joint" type="free" limited="false" />
        <site name="imu" size="0.01" pos="0.0 0 0.0" quat="1 0 0 0"/>
            <geom type="mesh" contype="0" conaffinity="0" group="1" rgba="1 1 1 1" mesh="base_link" />
            <geom type="mesh" rgba="1 1 1 1" mesh="base_link" />
            <body name="r_hip_pitch_link" pos="-0.010755 -0.022431 -0.085175">
                <inertial pos="-0.0024838 -0.073386 -7.2332e-05" quat="0.707107 0.707107 0 0" mass="0.384498" diaginertia="0.000324 0.000236 0.000192" />
                <joint name="r_hip_pitch_joint" pos="0 0 0" axis="0 1 0" limited="true" range="-1 1" />
                <geom type="mesh" contype="0" conaffinity="0" group="1" rgba="1 1 1 1" mesh="r_hip_pitch_link" />
                <geom type="mesh" rgba="1 1 1 1" mesh="r_hip_pitch_link" />
                <body name="r_hip_roll_link" pos="0.000365066 -0.0755015 -6.48896e-05">
                    <inertial pos="-0.00060502 0.0014424 -0.24367" quat="0.707107 0 0 0.707107" mass="0.620368" diaginertia="0.006366 0.00629 0.000344" />
                    <joint name="r_hip_roll_joint" pos="0 0 0" axis="-1 0 0" limited="true" range="-1 1" />
                    <geom type="mesh" contype="0" conaffinity="0" group="1" rgba="1 1 1 1" mesh="r_hip_roll_link" />
                    <body name="r_knee_pitch_link" pos="0.00036888 0 -0.304909">
                        <inertial pos="1.9035e-06 0.0019029 -0.14564" mass="0.271066" diaginertia="0.002117 0.002072 0.00012" />
                        <joint name="r_knee_pitch_joint" pos="0 0 0" axis="0 1 0" limited="true" range="-1 1" />
                        <geom type="mesh" contype="0" conaffinity="0" group="1" rgba="1 1 1 1" mesh="r_knee_pitch_link" />
                        <geom type="mesh" rgba="1 1 1 1" mesh="r_knee_pitch_link" />
                    </body>
                </body>
            </body>
            <body name="l_hip_pitch_link" pos="-0.0107552 0.0225656 -0.0851757">
                <inertial pos="-0.0024838 0.073386 -7.2332e-05" quat="0.707107 0.707107 0 0" mass="0.384498" diaginertia="0.000324 0.000236 0.000192" />
                <joint name="l_hip_pitch_joint" pos="0 0 0" axis="0 1 0" limited="true" range="-1 1" />
                <geom type="mesh" contype="0" conaffinity="0" group="1" rgba="1 1 1 1" mesh="l_hip_pitch_link" />
                <geom type="mesh" rgba="1 1 1 1" mesh="l_hip_pitch_link" />
                <body name="l_hip_roll_link" pos="0.00036517 0.0755015 -6.43024e-05">
                    <inertial pos="-0.0010784 -0.0032097 -0.24367" quat="0.707107 0 0 0.707107" mass="0.620368" diaginertia="0.006365 0.006291 0.000344" />
                    <joint name="l_hip_roll_joint" pos="0 0 0" axis="-1 0 0" limited="true" range="-1 1" />
                    <geom type="mesh" contype="0" conaffinity="0" group="1" rgba="1 1 1 1" mesh="l_hip_roll_link" />
                    <body name="l_knee_pitch_link" pos="-0.000365179 -0.00194284 -0.304906">
                        <inertial pos="-1.9035e-06 -0.0018987 -0.14564" mass="0.271066" diaginertia="0.002117 0.002072 0.00012" />
                        <joint name="l_knee_pitch_joint" pos="0 0 0" axis="0 1 0" limited="true" range="-1 1" />
                        <geom type="mesh" contype="0" conaffinity="0" group="1" rgba="1 1 1 1" mesh="l_knee_pitch_link" />
                        <geom type="mesh" rgba="1 1 1 1" mesh="l_knee_pitch_link" />
                    </body>
                </body>
            </body>
        </body>
    </worldbody>
    <actuator>
        <motor name="l_hip_roll" joint="l_hip_roll_joint" gear="1" ctrllimited="true" ctrlrange="-320 320"/>
        <motor name="l_hip_yaw" joint="l_hip_yaw_joint" gear="1" ctrllimited="true" ctrlrange="-160 160"/>
        <motor name="l_hip_pitch" joint="l_hip_pitch_joint" gear="1" ctrllimited="true" ctrlrange="-396 396"/>
        <motor name="l_knee_pitch" joint="l_knee_pitch_joint" gear="1" ctrllimited="true" ctrlrange="-396 396"/>
        <motor name="l_ankle_pitch" joint="l_ankle_pitch_joint" gear="1" ctrllimited="true" ctrlrange="-20 20"/>
        <motor name="r_hip_roll" joint="r_hip_roll_joint" gear="1" ctrllimited="true" ctrlrange="-320 320"/>
        <motor name="r_hip_yaw" joint="r_hip_yaw_joint" gear="1" ctrllimited="true" ctrlrange="-160 160"/>
        <motor name="r_hip_pitch" joint="r_hip_pitch_joint" gear="1" ctrllimited="true" ctrlrange="-396 396"/>
        <motor name="r_knee_pitch" joint="r_knee_pitch_joint" gear="1" ctrllimited="true" ctrlrange="-396 396"/>
        <motor name="r_ankle_pitch" joint="r_ankle_pitch_joint" gear="1" ctrllimited="true" ctrlrange="-20 20"/>
    </actuator>
    <sensor>
        <framequat name="orientation" objtype="site" noise="0.001" objname="imu"/>
        <framepos name="position" objtype="site" noise="0.001" objname="imu"/>
        <gyro name="angular-velocity" site="imu" noise="0.005" cutoff="34.9"/>
        <velocimeter name="linear-velocity" site="imu" noise="0.001" cutoff="30"/>
        <accelerometer name="linear-acceleration" site="imu" noise="0.005" cutoff="157"/>
        <magnetometer name="magnetometer" site="imu"/>
    </sensor>
</mujoco>
